<?xml version="1.0" encoding="UTF-8"?>
<testng-results skipped="1" failed="3" total="12" passed="8">
  <reporter-output>
  </reporter-output>
  <suite name="Suite_01" duration-ms="325" started-at="2020-07-14T10:33:54Z" finished-at="2020-07-14T10:33:54Z">
    <groups>
      <group name="func">
        <method signature="TC_01.method_01()[pri:2, instance:testcases.TC_01@28d25987]" name="method_01" class="testcases.TC_01"/>
        <method signature="TC_01.method_03()[pri:1, instance:testcases.TC_01@28d25987]" name="method_03" class="testcases.TC_01"/>
        <method signature="TC_02.method_05()[pri:6, instance:testcases.TC_02@4883b407]" name="method_05" class="testcases.TC_02"/>
        <method signature="TC_02.method_06()[pri:5, instance:testcases.TC_02@4883b407]" name="method_06" class="testcases.TC_02"/>
        <method signature="TC_02.method_07()[pri:4, instance:testcases.TC_02@4883b407]" name="method_07" class="testcases.TC_02"/>
      </group> <!-- func -->
      <group name="masters">
        <method signature="TC_01.method_01()[pri:2, instance:testcases.TC_01@28d25987]" name="method_01" class="testcases.TC_01"/>
        <method signature="TC_01.method_02()[pri:0, instance:testcases.TC_01@28d25987]" name="method_02" class="testcases.TC_01"/>
        <method signature="TC_01.method_04()[pri:3, instance:testcases.TC_01@28d25987]" name="method_04" class="testcases.TC_01"/>
        <method signature="TC_02.method_05()[pri:6, instance:testcases.TC_02@4883b407]" name="method_05" class="testcases.TC_02"/>
        <method signature="TC_02.method_06()[pri:5, instance:testcases.TC_02@4883b407]" name="method_06" class="testcases.TC_02"/>
        <method signature="TC_02.method_07()[pri:4, instance:testcases.TC_02@4883b407]" name="method_07" class="testcases.TC_02"/>
      </group> <!-- masters -->
    </groups>
    <test name="Listeners-Ex-Test-Group-01" duration-ms="189" started-at="2020-07-14T10:33:54Z" finished-at="2020-07-14T10:33:54Z">
      <class name="testcases.TC_01">
        <test-method status="PASS" signature="method_02()[pri:0, instance:testcases.TC_01@28d25987]" name="method_02" duration-ms="55" started-at="2020-07-14T16:03:54Z" finished-at="2020-07-14T16:03:54Z">
          <reporter-output>
          </reporter-output>
        </test-method> <!-- method_02 -->
        <test-method status="PASS" signature="method_03()[pri:1, instance:testcases.TC_01@28d25987]" name="method_03" duration-ms="3" started-at="2020-07-14T16:03:54Z" finished-at="2020-07-14T16:03:54Z">
          <reporter-output>
          </reporter-output>
        </test-method> <!-- method_03 -->
        <test-method status="PASS" signature="method_01()[pri:2, instance:testcases.TC_01@28d25987]" name="method_01" duration-ms="2" started-at="2020-07-14T16:03:54Z" finished-at="2020-07-14T16:03:54Z">
          <reporter-output>
          </reporter-output>
        </test-method> <!-- method_01 -->
        <test-method status="FAIL" signature="method_04()[pri:3, instance:testcases.TC_01@28d25987]" name="method_04" duration-ms="4" started-at="2020-07-14T16:03:54Z" finished-at="2020-07-14T16:03:54Z">
          <exception class="java.lang.AssertionError">
            <message>
              <![CDATA[expected [false] but found [true]]]>
            </message>
            <full-stacktrace>
              <![CDATA[java.lang.AssertionError: expected [false] but found [true]
	at org.testng.Assert.fail(Assert.java:94)
	at org.testng.Assert.failNotEquals(Assert.java:513)
	at org.testng.Assert.assertFalse(Assert.java:63)
	at org.testng.Assert.assertFalse(Assert.java:73)
	at testcases.TC_01.method_04(TC_01.java:33)
	at sun.reflect.NativeMethodAccessorImpl.invoke0(Native Method)
	at sun.reflect.NativeMethodAccessorImpl.invoke(NativeMethodAccessorImpl.java:62)
	at sun.reflect.DelegatingMethodAccessorImpl.invoke(DelegatingMethodAccessorImpl.java:43)
	at java.lang.reflect.Method.invoke(Method.java:498)
	at org.testng.internal.MethodInvocationHelper.invokeMethod(MethodInvocationHelper.java:100)
	at org.testng.internal.Invoker.invokeMethod(Invoker.java:646)
	at org.testng.internal.Invoker.invokeTestMethod(Invoker.java:811)
	at org.testng.internal.Invoker.invokeTestMethods(Invoker.java:1137)
	at org.testng.internal.TestMethodWorker.invokeTestMethods(TestMethodWorker.java:129)
	at org.testng.internal.TestMethodWorker.run(TestMethodWorker.java:112)
	at org.testng.TestRunner.privateRun(TestRunner.java:753)
	at org.testng.TestRunner.run(TestRunner.java:607)
	at org.testng.SuiteRunner.runTest(SuiteRunner.java:368)
	at org.testng.SuiteRunner.runSequentially(SuiteRunner.java:363)
	at org.testng.SuiteRunner.privateRun(SuiteRunner.java:321)
	at org.testng.SuiteRunner.run(SuiteRunner.java:270)
	at org.testng.SuiteRunnerWorker.runSuite(SuiteRunnerWorker.java:52)
	at org.testng.SuiteRunnerWorker.run(SuiteRunnerWorker.java:86)
	at org.testng.TestNG.runSuitesSequentially(TestNG.java:1284)
	at org.testng.TestNG.runSuitesLocally(TestNG.java:1209)
	at org.testng.TestNG.runSuites(TestNG.java:1124)
	at org.testng.TestNG.run(TestNG.java:1096)
	at org.testng.remote.AbstractRemoteTestNG.run(AbstractRemoteTestNG.java:132)
	at org.testng.remote.RemoteTestNG.initAndRun(RemoteTestNG.java:236)
	at org.testng.remote.RemoteTestNG.main(RemoteTestNG.java:81)
]]>
            </full-stacktrace>
          </exception> <!-- java.lang.AssertionError -->
          <reporter-output>
          </reporter-output>
        </test-method> <!-- method_04 -->
      </class> <!-- testcases.TC_01 -->
    </test> <!-- Listeners-Ex-Test-Group-01 -->
    <test name="Listeners-Ex-Test-Group-02" duration-ms="59" started-at="2020-07-14T10:33:54Z" finished-at="2020-07-14T10:33:54Z">
      <class name="testcases.TC_02">
        <test-method status="FAIL" signature="method_08()[pri:0, instance:testcases.TC_02@4883b407]" name="method_08" duration-ms="5" started-at="2020-07-14T16:03:54Z" finished-at="2020-07-14T16:03:54Z">
          <exception class="java.lang.AssertionError">
            <message>
              <![CDATA[expected [false] but found [true]]]>
            </message>
            <full-stacktrace>
              <![CDATA[java.lang.AssertionError: expected [false] but found [true]
	at org.testng.Assert.fail(Assert.java:94)
	at org.testng.Assert.failNotEquals(Assert.java:513)
	at org.testng.Assert.assertFalse(Assert.java:63)
	at org.testng.Assert.assertFalse(Assert.java:73)
	at testcases.TC_02.method_08(TC_02.java:33)
	at sun.reflect.NativeMethodAccessorImpl.invoke0(Native Method)
	at sun.reflect.NativeMethodAccessorImpl.invoke(NativeMethodAccessorImpl.java:62)
	at sun.reflect.DelegatingMethodAccessorImpl.invoke(DelegatingMethodAccessorImpl.java:43)
	at java.lang.reflect.Method.invoke(Method.java:498)
	at org.testng.internal.MethodInvocationHelper.invokeMethod(MethodInvocationHelper.java:100)
	at org.testng.internal.Invoker.invokeMethod(Invoker.java:646)
	at org.testng.internal.Invoker.invokeTestMethod(Invoker.java:811)
	at org.testng.internal.Invoker.invokeTestMethods(Invoker.java:1137)
	at org.testng.internal.TestMethodWorker.invokeTestMethods(TestMethodWorker.java:129)
	at org.testng.internal.TestMethodWorker.run(TestMethodWorker.java:112)
	at org.testng.TestRunner.privateRun(TestRunner.java:753)
	at org.testng.TestRunner.run(TestRunner.java:607)
	at org.testng.SuiteRunner.runTest(SuiteRunner.java:368)
	at org.testng.SuiteRunner.runSequentially(SuiteRunner.java:363)
	at org.testng.SuiteRunner.privateRun(SuiteRunner.java:321)
	at org.testng.SuiteRunner.run(SuiteRunner.java:270)
	at org.testng.SuiteRunnerWorker.runSuite(SuiteRunnerWorker.java:52)
	at org.testng.SuiteRunnerWorker.run(SuiteRunnerWorker.java:86)
	at org.testng.TestNG.runSuitesSequentially(TestNG.java:1284)
	at org.testng.TestNG.runSuitesLocally(TestNG.java:1209)
	at org.testng.TestNG.runSuites(TestNG.java:1124)
	at org.testng.TestNG.run(TestNG.java:1096)
	at org.testng.remote.AbstractRemoteTestNG.run(AbstractRemoteTestNG.java:132)
	at org.testng.remote.RemoteTestNG.initAndRun(RemoteTestNG.java:236)
	at org.testng.remote.RemoteTestNG.main(RemoteTestNG.java:81)
]]>
            </full-stacktrace>
          </exception> <!-- java.lang.AssertionError -->
          <reporter-output>
          </reporter-output>
        </test-method> <!-- method_08 -->
        <test-method status="PASS" signature="method_07()[pri:4, instance:testcases.TC_02@4883b407]" name="method_07" duration-ms="2" started-at="2020-07-14T16:03:54Z" finished-at="2020-07-14T16:03:54Z">
          <reporter-output>
          </reporter-output>
        </test-method> <!-- method_07 -->
        <test-method status="PASS" signature="method_06()[pri:5, instance:testcases.TC_02@4883b407]" name="method_06" duration-ms="2" started-at="2020-07-14T16:03:54Z" finished-at="2020-07-14T16:03:54Z">
          <reporter-output>
          </reporter-output>
        </test-method> <!-- method_06 -->
        <test-method status="SKIP" signature="method_05()[pri:6, instance:testcases.TC_02@4883b407]" name="method_05" duration-ms="0" started-at="2020-07-14T16:03:54Z" depends-on-methods="testcases.TC_02.method_08" finished-at="2020-07-14T16:03:54Z">
          <exception class="java.lang.Throwable">
            <message>
              <![CDATA[Method TC_02.method_05()[pri:6, instance:testcases.TC_02@4883b407] depends on not successfully finished methods]]>
            </message>
            <full-stacktrace>
              <![CDATA[java.lang.Throwable: Method TC_02.method_05()[pri:6, instance:testcases.TC_02@4883b407] depends on not successfully finished methods
	at org.testng.internal.Invoker.invokeTestMethods(Invoker.java:1028)
	at org.testng.internal.TestMethodWorker.invokeTestMethods(TestMethodWorker.java:129)
	at org.testng.internal.TestMethodWorker.run(TestMethodWorker.java:112)
	at org.testng.TestRunner.privateRun(TestRunner.java:753)
	at org.testng.TestRunner.run(TestRunner.java:607)
	at org.testng.SuiteRunner.runTest(SuiteRunner.java:368)
	at org.testng.SuiteRunner.runSequentially(SuiteRunner.java:363)
	at org.testng.SuiteRunner.privateRun(SuiteRunner.java:321)
	at org.testng.SuiteRunner.run(SuiteRunner.java:270)
	at org.testng.SuiteRunnerWorker.runSuite(SuiteRunnerWorker.java:52)
	at org.testng.SuiteRunnerWorker.run(SuiteRunnerWorker.java:86)
	at org.testng.TestNG.runSuitesSequentially(TestNG.java:1284)
	at org.testng.TestNG.runSuitesLocally(TestNG.java:1209)
	at org.testng.TestNG.runSuites(TestNG.java:1124)
	at org.testng.TestNG.run(TestNG.java:1096)
	at org.testng.remote.AbstractRemoteTestNG.run(AbstractRemoteTestNG.java:132)
	at org.testng.remote.RemoteTestNG.initAndRun(RemoteTestNG.java:236)
	at org.testng.remote.RemoteTestNG.main(RemoteTestNG.java:81)
]]>
            </full-stacktrace>
          </exception> <!-- java.lang.Throwable -->
          <reporter-output>
          </reporter-output>
        </test-method> <!-- method_05 -->
      </class> <!-- testcases.TC_02 -->
    </test> <!-- Listeners-Ex-Test-Group-02 -->
    <test name="Listeners-Ex-Test-Group-03" duration-ms="28" started-at="2020-07-14T10:33:54Z" finished-at="2020-07-14T10:33:54Z">
      <class name="testcases.TC_03">
        <test-method status="PASS" signature="method_09()[pri:0, instance:testcases.TC_03@548e7350]" name="method_09" duration-ms="2" started-at="2020-07-14T16:03:54Z" finished-at="2020-07-14T16:03:54Z">
          <reporter-output>
          </reporter-output>
        </test-method> <!-- method_09 -->
        <test-method status="PASS" signature="method_10()[pri:0, instance:testcases.TC_03@548e7350]" name="method_10" duration-ms="3" started-at="2020-07-14T16:03:54Z" finished-at="2020-07-14T16:03:54Z">
          <reporter-output>
          </reporter-output>
        </test-method> <!-- method_10 -->
        <test-method status="PASS" signature="method_11()[pri:0, instance:testcases.TC_03@548e7350]" name="method_11" duration-ms="4" started-at="2020-07-14T16:03:54Z" finished-at="2020-07-14T16:03:54Z">
          <reporter-output>
          </reporter-output>
        </test-method> <!-- method_11 -->
        <test-method status="FAIL" signature="method_12()[pri:0, instance:testcases.TC_03@548e7350]" name="method_12" duration-ms="2" started-at="2020-07-14T16:03:54Z" finished-at="2020-07-14T16:03:54Z">
          <exception class="java.lang.AssertionError">
            <message>
              <![CDATA[expected [false] but found [true]]]>
            </message>
            <full-stacktrace>
              <![CDATA[java.lang.AssertionError: expected [false] but found [true]
	at org.testng.Assert.fail(Assert.java:94)
	at org.testng.Assert.failNotEquals(Assert.java:513)
	at org.testng.Assert.assertFalse(Assert.java:63)
	at org.testng.Assert.assertFalse(Assert.java:73)
	at testcases.TC_03.method_12(TC_03.java:33)
	at sun.reflect.NativeMethodAccessorImpl.invoke0(Native Method)
	at sun.reflect.NativeMethodAccessorImpl.invoke(NativeMethodAccessorImpl.java:62)
	at sun.reflect.DelegatingMethodAccessorImpl.invoke(DelegatingMethodAccessorImpl.java:43)
	at java.lang.reflect.Method.invoke(Method.java:498)
	at org.testng.internal.MethodInvocationHelper.invokeMethod(MethodInvocationHelper.java:100)
	at org.testng.internal.Invoker.invokeMethod(Invoker.java:646)
	at org.testng.internal.Invoker.invokeTestMethod(Invoker.java:811)
	at org.testng.internal.Invoker.invokeTestMethods(Invoker.java:1137)
	at org.testng.internal.TestMethodWorker.invokeTestMethods(TestMethodWorker.java:129)
	at org.testng.internal.TestMethodWorker.run(TestMethodWorker.java:112)
	at org.testng.TestRunner.privateRun(TestRunner.java:753)
	at org.testng.TestRunner.run(TestRunner.java:607)
	at org.testng.SuiteRunner.runTest(SuiteRunner.java:368)
	at org.testng.SuiteRunner.runSequentially(SuiteRunner.java:363)
	at org.testng.SuiteRunner.privateRun(SuiteRunner.java:321)
	at org.testng.SuiteRunner.run(SuiteRunner.java:270)
	at org.testng.SuiteRunnerWorker.runSuite(SuiteRunnerWorker.java:52)
	at org.testng.SuiteRunnerWorker.run(SuiteRunnerWorker.java:86)
	at org.testng.TestNG.runSuitesSequentially(TestNG.java:1284)
	at org.testng.TestNG.runSuitesLocally(TestNG.java:1209)
	at org.testng.TestNG.runSuites(TestNG.java:1124)
	at org.testng.TestNG.run(TestNG.java:1096)
	at org.testng.remote.AbstractRemoteTestNG.run(AbstractRemoteTestNG.java:132)
	at org.testng.remote.RemoteTestNG.initAndRun(RemoteTestNG.java:236)
	at org.testng.remote.RemoteTestNG.main(RemoteTestNG.java:81)
]]>
            </full-stacktrace>
          </exception> <!-- java.lang.AssertionError -->
          <reporter-output>
          </reporter-output>
        </test-method> <!-- method_12 -->
      </class> <!-- testcases.TC_03 -->
    </test> <!-- Listeners-Ex-Test-Group-03 -->
  </suite> <!-- Suite_01 -->
</testng-results>
